Workbook

Sheet Portada
B3: SISTEMA DE EVALUACION NIVEL DE SEGURIDAD 2026
B7: Pilar 4 - Seguridad y Salud Ocupacional (WCM)
B10: Planta: | C10: CBC Guatemala - Cuyotenango, Suchitepequez
B11: Responsable SSO: | C11: Jaime Chilel
B12: Mes visualizado en Dashboard: | C12: =Calculos!$B$2 -> Septiembre
B13: Fecha de actualizacion: | C13: =TODAY() -> 46295
B14: No. de areas evaluadas: | C14: =15 -> 15
B15: Version del modelo: | C15: 2.0
B18: Contenido del Archivo
B19: Parametros | C19: Pesos de categorias, rangos de semaforo, listado de las 15 areas
B20: Captura [Mes] | C20: 12 hojas (Enero a Diciembre) - ingreso mensual de datos por cada una de las 15 areas
B21: Calculos | C21: Motor de calculo con selector de mes - resumenes y ranking (uso interno)
B22: Dashboard Ejecutivo | C22: KPIs, semaforos y graficos para presentacion gerencial del mes seleccionado
B23: Historico | C23: Registro mensual del Nivel de Seguridad de planta para analisis de tendencia
B24: Acumulado 2026 | C24: Matriz Area x Mes con el acumulado anual de cada area y el promedio de planta

Sheet Calculos
A1: MOTOR DE CALCULO (uso interno - puede ocultarse)
A2: Mes a visualizar en Dashboard: | B2: Septiembre
A3: Resumen por Categoria (Nivel Planta) - Mes seleccionado
A4: Categoria | B4: Peso Maximo | C4: Promedio Obtenido (planta) | D4: % Cumplimiento vs Peso
A5: Capacitaciones | B5: =Parametros!E6 -> 0.2 | C5: =AVERAGE(INDIRECT("'Captura "&Calculos!$B$2&"'!"&"G6"):INDIRECT("'Captura "&Calculos!$B$2&"'!"&"G20")) -> 0.18731333 | D5: =IFERROR(C5/B5,0) -> 0.93656667
A6: Auto Evaluacion 1 | B6: =Parametros!E7 -> 0.08 | C6: =AVERAGE(INDIRECT("'Captura "&Calculos!$B$2&"'!"&"K6"):INDIRECT("'Captura "&Calculos!$B$2&"'!"&"K20")) -> 0.08 | D6: =IFERROR(C6/B6,0) -> 1
A7: Auto Evaluacion 2 | B7: =Parametros!E8 -> 0.08 | C7: =AVERAGE(INDIRECT("'Captura "&Calculos!$B$2&"'!"&"N6"):INDIRECT("'Captura "&Calculos!$B$2&"'!"&"N20")) -> 0.077546667 | D7: =IFERROR(C7/B7,0) -> 0.96933333
A8: Auto Evaluacion 3 | B8: =Parametros!E9 -> 0.08 | C8: =AVERAGE(INDIRECT("'Captura "&Calculos!$B$2&"'!"&"N6"):INDIRECT("'Captura "&Calculos!$B$2&"'!"&"N20")) -> 0.077546667 | D8: =IFERROR(C8/B8,0) -> 0.96933333
A9: Cruzada 4 | B9: =Parametros!E10 -> 0.06 | C9: =AVERAGE(INDIRECT("'Captura "&Calculos!$B$2&"'!"&"T6"):INDIRECT("'Captura "&Calculos!$B$2&"'!"&"T20")) -> 0.024 | D9: =IFERROR(C9/B9,0) -> 0.4
A10: Inspeccion SSO | B10: =Parametros!E11 -> 0.25 | C10: =AVERAGE(INDIRECT("'Captura "&Calculos!$B$2&"'!"&"V6"):INDIRECT("'Captura "&Calculos!$B$2&"'!"&"V20")) -> 0.2382 | D10: =IFERROR(C10/B10,0) -> 0.9528
A11: Acciones Correctivas/Preventivas | B11: =Parametros!E12 -> 0.25 | C11: =AVERAGE(INDIRECT("'Captura "&Calculos!$B$2&"'!"&"X6"):INDIRECT("'Captura "&Calculos!$B$2&"'!"&"X20")) -> 0.14333333 | D11: =IFERROR(C11/B11,0) -> 0.57333333
A13: Cultura y Accidentabilidad (Nivel Planta) - Mes seleccionado
A14: Bono promedio Cultura otorgado (planta) | B14: =AVERAGE(INDIRECT("'Captura "&Calculos!$B$2&"'!"&"X6"):INDIRECT("'Captura "&Calculos!$B$2&"'!"&"X20")) -> 0.14333333
A15: No. de areas con bonificacion completa (4%) | B15: =COUNTIF(INDIRECT("'Captura "&Calculos!$B$2&"'!"&"X6"):INDIRECT("'Captura "&Calculos!$B$2&"'!"&"X20"),">=0.04") -> 12
A16: Penalizacion promedio Accidentabilidad (planta) | B16: =AVERAGE(INDIRECT("'Captura "&Calculos!$B$2&"'!"&"AN6"):INDIRECT("'Captura "&Calculos!$B$2&"'!"&"AN20")) -> 0.016666667
A17: No. de areas con evento NO reportado | B17: =COUNTIF(INDIRECT("'Captura "&Calculos!$B$2&"'!"&"AJ6"):INDIRECT("'Captura "&Calculos!$B$2&"'!"&"AJ20"),"SI") -> 0
A18: Total LTI en planta (mes) | B18: =SUM(INDIRECT("'Captura "&Calculos!$B$2&"'!"&"AL6"):INDIRECT("'Captura "&Calculos!$B$2&"'!"&"AL20")) -> 0
A19: Total MDI en planta (mes) | B19: =SUM(INDIRECT("'Captura "&Calculos!$B$2&"'!"&"AJ6"):INDIRECT("'Captura "&Calculos!$B$2&"'!"&"AJ20")) -> 0
A21: Ranking de Areas (Nivel de Seguridad) - Mes seleccionado
A22: Pos. | B22: Area | C22: Nivel Seguridad | D22: Semaforo | E22: (aux)
A23: 1 | B23: =INDEX(INDIRECT("'Captura "&Calculos!$B$2&"'!"&"B6"):INDIRECT("'Captura "&Calculos!$B$2&"'!"&"B20"),MATCH(LARGE($E$23:$E$37,1),$E$23:$E$37,0)) -> Calidad | C23: =LARGE(INDIRECT("'Captura "&Calculos!$B$2&"'!"&"AL6"):INDIRECT("'Captura "&Calculos!$B$2&"'!"&"AL20"),1) -> 0 | D23: =IF(C23>=Parametros!$C$37,"Verde",IF(C23>=Parametros!$C$38,"Amarillo","Rojo")) -> Rojo | E23: =INDIRECT("'Captura "&Calculos!$B$2&"'!"&"AL6")*100000-6 -> -6
A24: 2 | B24: =INDEX(INDIRECT("'Captura "&Calculos!$B$2&"'!"&"B6"):INDIRECT("'Captura "&Calculos!$B$2&"'!"&"B20"),MATCH(LARGE($E$23:$E$37,2),$E$23:$E$37,0)) -> Jarabes | C24: =LARGE(INDIRECT("'Captura "&Calculos!$B$2&"'!"&"AL6"):INDIRECT("'Captura "&Calculos!$B$2&"'!"&"AL20"),2) -> 0 | D24: =IF(C24>=Parametros!$C$37,"Verde",IF(C24>=Parametros!$C$38,"Amarillo","Rojo")) -> Rojo | E24: =INDIRECT("'Captura "&Calculos!$B$2&"'!"&"AQ7")*100000-7 -> 55043
A25: 3 | B25: =INDEX(INDIRECT("'Captura "&Calculos!$B$2&"'!"&"B6"):INDIRECT("'Captura "&Calculos!$B$2&"'!"&"B20"),MATCH(LARGE($E$23:$E$37,3),$E$23:$E$37,0)) -> ETEI | C25: =LARGE(INDIRECT("'Captura "&Calculos!$B$2&"'!"&"AL6"):INDIRECT("'Captura "&Calculos!$B$2&"'!"&"AL20"),3) -> 0 | D25: =IF(C25>=Parametros!$C$37,"Verde",IF(C25>=Parametros!$C$38,"Amarillo","Rojo")) -> Rojo | E25: =INDIRECT("'Captura "&Calculos!$B$2&"'!"&"AQ8")*100000-8 -> 99992
A26: 4 | B26: =INDEX(INDIRECT("'Captura "&Calculos!$B$2&"'!"&"B6"):INDIRECT("'Captura "&Calculos!$B$2&"'!"&"B20"),MATCH(LARGE($E$23:$E$37,4),$E$23:$E$37,0)) -> Linea 4 | C26: =LARGE(INDIRECT("'Captura "&Calculos!$B$2&"'!"&"AL6"):INDIRECT("'Captura "&Calculos!$B$2&"'!"&"AL20"),4) -> 0 | D26: =IF(C26>=Parametros!$C$37,"Verde",IF(C26>=Parametros!$C$38,"Amarillo","Rojo")) -> Rojo | E26: =INDIRECT("'Captura "&Calculos!$B$2&"'!"&"AQ9")*100000-9 -> 86666
A27: 5 | B27: =INDEX(INDIRECT("'Captura "&Calculos!$B$2&"'!"&"B6"):INDIRECT("'Captura "&Calculos!$B$2&"'!"&"B20"),MATCH(LARGE($E$23:$E$37,5),$E$23:$E$37,0)) -> Mantenimiento | C27: =LARGE(INDIRECT("'Captura "&Calculos!$B$2&"'!"&"AL6"):INDIRECT("'Captura "&Calculos!$B$2&"'!"&"AL20"),5) -> 0 | D27: =IF(C27>=Parametros!$C$37,"Verde",IF(C27>=Parametros!$C$38,"Amarillo","Rojo")) -> Rojo | E27: =INDIRECT("'Captura "&Calculos!$B$2&"'!"&"AQ10")*100000-10 -> 97290
A28: 6 | B28: =INDEX(INDIRECT("'Captura "&Calculos!$B$2&"'!"&"B6"):INDIRECT("'Captura "&Calculos!$B$2&"'!"&"B20"),MATCH(LARGE($E$23:$E$37,6),$E$23:$E$37,0)) -> Centro de Distribucion | C28: =LARGE(INDIRECT("'Captura "&Calculos!$B$2&"'!"&"AL6"):INDIRECT("'Captura "&Calculos!$B$2&"'!"&"AL20"),6) -> 0 | D28: =IF(C28>=Parametros!$C$37,"Verde",IF(C28>=Parametros!$C$38,"Amarillo","Rojo")) -> Rojo | E28: =INDIRECT("'Captura "&Calculos!$B$2&"'!"&"AQ11")*100000-11 -> 81759
A29: 7 | B29: =INDEX(INDIRECT("'Captura "&Calculos!$B$2&"'!"&"B6"):INDIRECT("'Captura "&Calculos!$B$2&"'!"&"B20"),MATCH(LARGE($E$23:$E$37,7),$E$23:$E$37,0)) -> Materias Primas | C29: =LARGE(INDIRECT("'Captura "&Calculos!$B$2&"'!"&"AL6"):INDIRECT("'Captura "&Calculos!$B$2&"'!"&"AL20"),7) -> 0 | D29: =IF(C29>=Parametros!$C$37,"Verde",IF(C29>=Parametros!$C$38,"Amarillo","Rojo")) -> Rojo | E29: =INDIRECT("'Captura "&Calculos!$B$2&"'!"&"AQ12")*100000-12 -> 99988
A30: 8 | B30: =INDEX(INDIRECT("'Captura "&Calculos!$B$2&"'!"&"B6"):INDIRECT("'Captura "&Calculos!$B$2&"'!"&"B20"),MATCH(LARGE($E$23:$E$37,8),$E$23:$E$37,0)) -> Equipos Auxiliares | C30: =LARGE(INDIRECT("'Captura "&Calculos!$B$2&"'!"&"AL6"):INDIRECT("'Captura "&Calculos!$B$2&"'!"&"AL20"),8) -> 0 | D30: =IF(C30>=Parametros!$C$37,"Verde",IF(C30>=Parametros!$C$38,"Amarillo","Rojo")) -> Rojo | E30: =INDIRECT("'Captura "&Calculos!$B$2&"'!"&"AQ13")*100000-13 -> 69611
A31: 9 | B31: =INDEX(INDIRECT("'Captura "&Calculos!$B$2&"'!"&"B6"):INDIRECT("'Captura "&Calculos!$B$2&"'!"&"B20"),MATCH(LARGE($E$23:$E$37,9),$E$23:$E$37,0)) -> Linea 3 | C31: =LARGE(INDIRECT("'Captura "&Calculos!$B$2&"'!"&"AL6"):INDIRECT("'Captura "&Calculos!$B$2&"'!"&"AL20"),9) -> 0 | D31: =IF(C31>=Parametros!$C$37,"Verde",IF(C31>=Parametros!$C$38,"Amarillo","Rojo")) -> Rojo | E31: =INDIRECT("'Captura "&Calculos!$B$2&"'!"&"AQ14")*100000-14 -> 76487
A32: 10 | B32: =INDEX(INDIRECT("'Captura "&Calculos!$B$2&"'!"&"B6"):INDIRECT("'Captura "&Calculos!$B$2&"'!"&"B20"),MATCH(LARGE($E$23:$E$37,10),$E$23:$E$37,0)) -> Linea 2 | C32: =LARGE(INDIRECT("'Captura "&Calculos!$B$2&"'!"&"AL6"):INDIRECT("'Captura "&Calculos!$B$2&"'!"&"AL20"),10) -> 0 | D32: =IF(C32>=Parametros!$C$37,"Verde",IF(C32>=Parametros!$C$38,"Amarillo","Rojo")) -> Rojo | E32: =INDIRECT("'Captura "&Calculos!$B$2&"'!"&"AQ15")*100000-15 -> 77840
A33: 11 | B33: =INDEX(INDIRECT("'Captura "&Calculos!$B$2&"'!"&"B6"):INDIRECT("'Captura "&Calculos!$B$2&"'!"&"B20"),MATCH(LARGE($E$23:$E$37,11),$E$23:$E$37,0)) -> Linea 1 | C33: =LARGE(INDIRECT("'Captura "&Calculos!$B$2&"'!"&"AL6"):INDIRECT("'Captura "&Calculos!$B$2&"'!"&"AL20"),11) -> 0 | D33: =IF(C33>=Parametros!$C$37,"Verde",IF(C33>=Parametros!$C$38,"Amarillo","Rojo")) -> Rojo | E33: =INDIRECT("'Captura "&Calculos!$B$2&"'!"&"AQ16")*100000-16 -> 91819
A34: 12 | B34: =INDEX(INDIRECT("'Captura "&Calculos!$B$2&"'!"&"B6"):INDIRECT("'Captura "&Calculos!$B$2&"'!"&"B20"),MATCH(LARGE($E$23:$E$37,12),$E$23:$E$37,0)) -> Linea 5 | C34: =LARGE(INDIRECT("'Captura "&Calculos!$B$2&"'!"&"AL6"):INDIRECT("'Captura "&Calculos!$B$2&"'!"&"AL20"),12) -> 0 | D34: =IF(C34>=Parametros!$C$37,"Verde",IF(C34>=Parametros!$C$38,"Amarillo","Rojo")) -> Rojo | E34: =INDIRECT("'Captura "&Calculos!$B$2&"'!"&"AQ17")*100000-17 -> 61798
A35: 13 | B35: =INDEX(INDIRECT("'Captura "&Calculos!$B$2&"'!"&"B6"):INDIRECT("'Captura "&Calculos!$B$2&"'!"&"B20"),MATCH(LARGE($E$23:$E$37,13),$E$23:$E$37,0)) -> Alrededores | C35: =LARGE(INDIRECT("'Captura "&Calculos!$B$2&"'!"&"AL6"):INDIRECT("'Captura "&Calculos!$B$2&"'!"&"AL20"),13) -> 0 | D35: =IF(C35>=Parametros!$C$37,"Verde",IF(C35>=Parametros!$C$38,"Amarillo","Rojo")) -> Rojo | E35: =INDIRECT("'Captura "&Calculos!$B$2&"'!"&"AQ18")*100000-18 -> 91272
A36: 14 | B36: =INDEX(INDIRECT("'Captura "&Calculos!$B$2&"'!"&"B6"):INDIRECT("'Captura "&Calculos!$B$2&"'!"&"B20"),MATCH(LARGE($E$23:$E$37,14),$E$23:$E$37,0)) -> Almacen de Repuestos | C36: =LARGE(INDIRECT("'Captura "&Calculos!$B$2&"'!"&"AL6"):INDIRECT("'Captura "&Calculos!$B$2&"'!"&"AL20"),14) -> 0 | D36: =IF(C36>=Parametros!$C$37,"Verde",IF(C36>=Parametros!$C$38,"Amarillo","Rojo")) -> Rojo | E36: =INDIRECT("'Captura "&Calculos!$B$2&"'!"&"AQ19")*100000-19 -> 86106
A37: 15 | B37: =INDEX(INDIRECT("'Captura "&Calculos!$B$2&"'!"&"B6"):INDIRECT("'Captura "&Calculos!$B$2&"'!"&"B20"),MATCH(LARGE($E$23:$E$37,15),$E$23:$E$37,0)) -> Tratamiento de Aguas | C37: =LARGE(INDIRECT("'Captura "&Calculos!$B$2&"'!"&"AL6"):INDIRECT("'Captura "&Calculos!$B$2&"'!"&"AL20"),15) -> 0 | D37: =IF(C37>=Parametros!$C$37,"Verde",IF(C37>=Parametros!$C$38,"Amarillo","Rojo")) -> Rojo | E37: =INDIRECT("'Captura "&Calculos!$B$2&"'!"&"AL20")*100000-20 -> -20
A39: Conteo de Areas por Semaforo
A40: Verde | B40: =COUNTIF(D23:D37,"Verde") -> 0
A41: Amarillo | B41: =COUNTIF(D23:D37,"Amarillo") -> 0
A42: Rojo | B42: =COUNTIF(D23:D37,"Rojo") -> 15
A44: Nivel de Seguridad de Planta (mes seleccionado): | B44: =INDIRECT("'Captura "&Calculos!$B$2&"'!"&"AQ23") -> 0.83891667
...

Sheet Dashboard Ejecutivo
B2: DASHBOARD EJECUTIVO - NIVEL DE SEGURIDAD
B4: Mes a visualizar: | C4: =Calculos!$B$2 -> Septiembre | F4: Planta: CBC Guatemala - Cuyotenango, Suchitepequez
B6: NIVEL DE SEGURIDAD DE PLANTA | F6: SEMAFORO DE PLANTA | J6: AREAS EN VERDE | M6: AREAS EN AMARILLO | P6: AREAS EN ROJO
B8: =Calculos!B44 -> 0.83891667 | F8: =Calculos!B45 -> Amarillo | J8: =Calculos!B40 -> 0 | M8: =Calculos!B41 -> 0 | P8: =Calculos!B42 -> 15
B12: Nivel de Seguridad por Area (ordenado) | G12: Categoria (Radar)
B13: Area | C13: Nivel | G13: Categoria | H13: % Cumpl.
B14: =Calculos!B23 -> Calidad | C14: =Calculos!C23 -> 0 | G14: =Calculos!A5 -> Capacitaciones | H14: =Calculos!D5 -> 0.93656667
B15: =Calculos!B24 -> Jarabes | C15: =Calculos!C24 -> 0 | G15: =Calculos!A6 -> Auto Evaluacion 1 | H15: =Calculos!D6 -> 1
B16: =Calculos!B25 -> ETEI | C16: =Calculos!C25 -> 0 | G16: =Calculos!A7 -> Auto Evaluacion 2 | H16: =Calculos!D7 -> 0.96933333
B17: =Calculos!B26 -> Linea 4 | C17: =Calculos!C26 -> 0 | G17: =Calculos!A8 -> Auto Evaluacion 3 | H17: =Calculos!D8 -> 0.96933333
B18: =Calculos!B27 -> Mantenimiento | C18: =Calculos!C27 -> 0 | G18: =Calculos!A9 -> Cruzada 4 | H18: =Calculos!D9 -> 0.4
B19: =Calculos!B28 -> Centro de Distribucion | C19: =Calculos!C28 -> 0 | G19: =Calculos!A10 -> Inspeccion SSO | H19: =Calculos!D10 -> 0.9528
B20: =Calculos!B29 -> Materias Primas | C20: =Calculos!C29 -> 0 | G20: =Calculos!A11 -> Acciones Correctivas/Preventivas | H20: =Calculos!D11 -> 0.57333333
B21: =Calculos!B30 -> Equipos Auxiliares | C21: =Calculos!C30 -> 0
B22: =Calculos!B31 -> Linea 3 | C22: =Calculos!C31 -> 0
B23: =Calculos!B32 -> Linea 2 | C23: =Calculos!C32 -> 0
B24: =Calculos!B33 -> Linea 1 | C24: =Calculos!C33 -> 0
B25: =Calculos!B34 -> Linea 5 | C25: =Calculos!C34 -> 0
B26: =Calculos!B35 -> Alrededores | C26: =Calculos!C35 -> 0
B27: =Calculos!B36 -> Almacen de Repuestos | C27: =Calculos!C36 -> 0
B28: =Calculos!B37 -> Tratamiento de Aguas | C28: =Calculos!C37 -> 0
T48: Verde | U48: =Calculos!B40 -> 0
T49: Amarillo | U49: =Calculos!B41 -> 0
T50: Rojo | U50: =Calculos!B42 -> 15

Sheet Triángulo Accidentabilidad
B2: Mes: | E2: Septiembre | H2: → Haz clic en la celda amarilla y elige el mes del menú desplegable
B4: TRIÁNGULO DE ACCIDENTABILIDAD
B5: =UPPER("Planta Cuyotenango · "&Calculos!$B$2&" 2026 · Acumulado Año") -> PLANTA CUYOTENANGO · SEPTIEMBRE 2026 · ACUMULADO AÑO
P6: Evento | Q6: Acum. Año
A7: =UPPER(Calculos!$B$2) -> SEPTIEMBRE | H7: =X30 -> 0 | P7: MUERTE | Q7: =Y30 -> 0
G8: =X31 -> 0 | P8: LTI | Q8: =Y31 -> 0
F9: =X32 -> 0 | P9: MDI | Q9: =Y32 -> 0
E10: =X33 -> 1 | P10: MTI | Q10: =Y33 -> 4
D11: =X34 -> 1 | P11: FAI | Q11: =Y34 -> 8
C12: =X35 -> 0 | P12: INCIDENTES | Q12: =Y35 -> 4
B13: =X36 -> 50 | P13: ACTOS | Q13: =Y36 -> 513
B14: =X37 -> 247 | P14: CONDICIONES | Q14: =Y37 -> 2171
S16: Días sin accidentes
S18: =IF(T20="","—",INT(TODAY()-T20)) -> 426 | U18: =IF(V20="","—",INT(TODAY()-V20)) -> 14
S19: LTI | U19: MTI
S20: Último: | T20: 45869 | U20: Último: | V20: 46281
S22: =IF(T24="","—",INT(TODAY()-T24)) -> 329 | U22: =IF(V24="","—",INT(TODAY()-V24)) -> 4
S23: MDI | U23: FAI
S24: Último: | T24: 45966 | U24: Último: | V24: 46291
B27: 📝 INSTRUCCIONES: Actos y Condiciones → ingresa el total en cada hoja de Captura (cuadro azul 'CULTURA' en columna BB). Días sin accidentes → ingresa la fecha del ÚLTIMO accidente en celdas amarillas (formato DD/MM/AAAA) — los días se calculan automáticamente cada día. | Muerte → celda X30
W30: MUERTE | X30: 0 | Y30: 0
W31: LTI | X31: =IFERROR(INDIRECT("'Captura "&Calculos!$B$2&"'!AL6")+INDIRECT("'Captura "&Calculos!$B$2&"'!AL7")+INDIRECT("'Captura "&Calculos!$B$2&"'!AL8")+INDIRECT("'Captura "&Calculos!$B$2&"'!AL9")+INDIRECT("'Captura "&Calculos!$B$2&"'!AL10")+INDIRECT("'Captura "&Calculos!$B$2&"'!AL11")+INDIRECT("'Captura "&Calculos!$B$2&"'!AL12")+INDIRECT("'Captura "&Calculos!$B$2&"'!AL13")+INDIRECT("'Captura "&Calculos!$B$2&"'!AL14")+INDIRECT("'Captura "&Calculos!$B$2&"'!AL15")+INDIRECT("'Captura "&Calculos!$B$2&"'!AL16")+INDIRECT("'Captura "&Calculos!$B$2&"'!AL17")+INDIRECT("'Captura "&Calculos!$B$2&"'!AL18")+INDIRECT("'Captura "&Calculos!$B$2&"'!AL19")+INDIRECT("'Captura "&Calculos!$B$2&"'!AL20"),0) -> 0 | Y31: =SUM('Captura Enero'!AL6:AL20)+SUM('Captura Febrero'!AL6:AL20)+SUM('Captura Marzo'!AL6:AL20)+SUM('Captura Abril'!AL6:AL20)+SUM('Captura Mayo'!AL6:AL20)+SUM('Captura Junio'!AL6:AL20)+SUM('Captura Julio'!AL6:AL20)+SUM('Captura Agosto'!AL6:AL20)+SUM('Captura Septiembre'!AL6:AL20)+SUM('Captura Octubre'!AL6:AL20)+SUM('Captura Noviembre'!AL6:AL20)+SUM('Captura Diciembre'!AL6:AL20) -> 0
W32: MDI | X32: =IFERROR(INDIRECT("'Captura "&Calculos!$B$2&"'!AJ6")+INDIRECT("'Captura "&Calculos!$B$2&"'!AJ7")+INDIRECT("'Captura "&Calculos!$B$2&"'!AJ8")+INDIRECT("'Captura "&Calculos!$B$2&"'!AJ9")+INDIRECT("'Captura "&Calculos!$B$2&"'!AJ10")+INDIRECT("'Captura "&Calculos!$B$2&"'!AJ11")+INDIRECT("'Captura "&Calculos!$B$2&"'!AJ12")+INDIRECT("'Captura "&Calculos!$B$2&"'!AJ13")+INDIRECT("'Captura "&Calculos!$B$2&"'!AJ14")+INDIRECT("'Captura "&Calculos!$B$2&"'!AJ15")+INDIRECT("'Captura "&Calculos!$B$2&"'!AJ16")+INDIRECT("'Captura "&Calculos!$B$2&"'!AJ17")+INDIRECT("'Captura "&Calculos!$B$2&"'!AJ18")+INDIRECT("'Captura "&Calculos!$B$2&"'!AJ19")+INDIRECT("'Captura "&Calculos!$B$2&"'!AJ20"),0) -> 0 | Y32: =SUM('Captura Enero'!AJ6:AJ20)+SUM('Captura Febrero'!AJ6:AJ20)+SUM('Captura Marzo'!AJ6:AJ20)+SUM('Captura Abril'!AJ6:AJ20)+SUM('Captura Mayo'!AJ6:AJ20)+SUM('Captura Junio'!AJ6:AJ20)+SUM('Captura Julio'!AJ6:AJ20)+SUM('Captura Agosto'!AJ6:AJ20)+SUM('Captura Septiembre'!AJ6:AJ20)+SUM('Captura Octubre'!AJ6:AJ20)+SUM('Captura Noviembre'!AJ6:AJ20)+SUM('Captura Diciembre'!AJ6:AJ20) -> 0
W33: MTI | X33: =IFERROR(INDIRECT("'Captura "&Calculos!$B$2&"'!AH6")+INDIRECT("'Captura "&Calculos!$B$2&"'!AH7")+INDIRECT("'Captura "&Calculos!$B$2&"'!AH8")+INDIRECT("'Captura "&Calculos!$B$2&"'!AH9")+INDIRECT("'Captura "&Calculos!$B$2&"'!AH10")+INDIRECT("'Captura "&Calculos!$B$2&"'!AH11")+INDIRECT("'Captura "&Calculos!$B$2&"'!AH12")+INDIRECT("'Captura "&Calculos!$B$2&"'!AH13")+INDIRECT("'Captura "&Calculos!$B$2&"'!AH14")+INDIRECT("'Captura "&Calculos!$B$2&"'!AH15")+INDIRECT("'Captura "&Calculos!$B$2&"'!AH16")+INDIRECT("'Captura "&Calculos!$B$2&"'!AH17")+INDIRECT("'Captura "&Calculos!$B$2&"'!AH18")+INDIRECT("'Captura "&Calculos!$B$2&"'!AH19")+INDIRECT("'Captura "&Calculos!$B$2&"'!AH20"),0) -> 1 | Y33: =SUM('Captura Enero'!AH6:AH20)+SUM('Captura Febrero'!AH6:AH20)+SUM('Captura Marzo'!AH6:AH20)+SUM('Captura Abril'!AH6:AH20)+SUM('Captura Mayo'!AH6:AH20)+SUM('Captura Junio'!AH6:AH20)+SUM('Captura Julio'!AH6:AH20)+SUM('Captura Agosto'!AH6:AH20)+SUM('Captura Septiembre'!AH6:AH20)+SUM('Captura Octubre'!AH6:AH20)+SUM('Captura Noviembre'!AH6:AH20)+SUM('Captura Diciembre'!AH6:AH20) -> 4
W34: FAI | X34: =IFERROR(INDIRECT("'Captura "&Calculos!$B$2&"'!AF6")+INDIRECT("'Captura "&Calculos!$B$2&"'!AF7")+INDIRECT("'Captura "&Calculos!$B$2&"'!AF8")+INDIRECT("'Captura "&Calculos!$B$2&"'!AF9")+INDIRECT("'Captura "&Calculos!$B$2&"'!AF10")+INDIRECT("'Captura "&Calculos!$B$2&"'!AF11")+INDIRECT("'Captura "&Calculos!$B$2&"'!AF12")+INDIRECT("'Captura "&Calculos!$B$2&"'!AF13")+INDIRECT("'Captura "&Calculos!$B$2&"'!AF14")+INDIRECT("'Captura "&Calculos!$B$2&"'!AF15")+INDIRECT("'Captura "&Calculos!$B$2&"'!AF16")+INDIRECT("'Captura "&Calculos!$B$2&"'!AF17")+INDIRECT("'Captura "&Calculos!$B$2&"'!AF18")+INDIRECT("'Captura "&Calculos!$B$2&"'!AF19")+INDIRECT("'Captura "&Calculos!$B$2&"'!AF20"),0) -> 1 | Y34: =SUM('Captura Enero'!AF6:AF20)+SUM('Captura Febrero'!AF6:AF20)+SUM('Captura Marzo'!AF6:AF20)+SUM('Captura Abril'!AF6:AF20)+SUM('Captura Mayo'!AF6:AF20)+SUM('Captura Junio'!AF6:AF20)+SUM('Captura Julio'!AF6:AF20)+SUM('Captura Agosto'!AF6:AF20)+SUM('Captura Septiembre'!AF6:AF20)+SUM('Captura Octubre'!AF6:AF20)+SUM('Captura Noviembre'!AF6:AF20)+SUM('Captura Diciembre'!AF6:AF20) -> 8
W35: INCIDENTES | X35: =IFERROR(INDIRECT("'Captura "&Calculos!$B$2&"'!AD6")+INDIRECT("'Captura "&Calculos!$B$2&"'!AD7")+INDIRECT("'Captura "&Calculos!$B$2&"'!AD8")+INDIRECT("'Captura "&Calculos!$B$2&"'!AD9")+INDIRECT("'Captura "&Calculos!$B$2&"'!AD10")+INDIRECT("'Captura "&Calculos!$B$2&"'!AD11")+INDIRECT("'Captura "&Calculos!$B$2&"'!AD12")+INDIRECT("'Captura "&Calculos!$B$2&"'!AD13")+INDIRECT("'Captura "&Calculos!$B$2&"'!AD14")+INDIRECT("'Captura "&Calculos!$B$2&"'!AD15")+INDIRECT("'Captura "&Calculos!$B$2&"'!AD16")+INDIRECT("'Captura "&Calculos!$B$2&"'!AD17")+INDIRECT("'Captura "&Calculos!$B$2&"'!AD18")+INDIRECT("'Captura "&Calculos!$B$2&"'!AD19")+INDIRECT("'Captura "&Calculos!$B$2&"'!AD20"),0) -> 0 | Y35: =SUM('Captura Enero'!AD6:AD20)+SUM('Captura Febrero'!AD6:AD20)+SUM('Captura Marzo'!AD6:AD20)+SUM('Captura Abril'!AD6:AD20)+SUM('Captura Mayo'!AD6:AD20)+SUM('Captura Junio'!AD6:AD20)+SUM('Captura Julio'!AD6:AD20)+SUM('Captura Agosto'!AD6:AD20)+SUM('Captura Septiembre'!AD6:AD20)+SUM('Captura Octubre'!AD6:AD20)+SUM('Captura Noviembre'!AD6:AD20)+SUM('Captura Diciembre'!AD6:AD20) -> 4
W36: ACTOS | X36: =IFERROR(INDIRECT("'Captura "&Calculos!$B$2&"'!BC3"),0) -> 50 | Y36: ='Captura Enero'!BC3+'Captura Febrero'!BC3+'Captura Marzo'!BC3+'Captura Abril'!BC3+'Captura Mayo'!BC3+'Captura Junio'!BC3+'Captura Julio'!BC3+'Captura Agosto'!BC3+'Captura Septiembre'!BC3+'Captura Octubre'!BC3+'Captura Noviembre'!BC3+'Captura Diciembre'!BC3 -> 513
W37: CONDICIONES | X37: =IFERROR(INDIRECT("'Captura "&Calculos!$B$2&"'!BC4"),0) -> 247 | Y37: ='Captura Enero'!BC4+'Captura Febrero'!BC4+'Captura Marzo'!BC4+'Captura Abril'!BC4+'Captura Mayo'!BC4+'Captura Junio'!BC4+'Captura Julio'!BC4+'Captura Agosto'!BC4+'Captura Septiembre'!BC4+'Captura Octubre'!BC4+'Captura Noviembre'!BC4+'Captura Diciembre'!BC4 -> 2171

Sheet Parametros
B2: PARAMETROS DEL MODELO - NIVEL DE SEGURIDAD 2026
B4: Categorias de Evaluacion y Ponderacion | H4: Listado de Areas Operativas
B5: Codigo | C5: Categoria | D5: Grupo | E5: Peso | F5: Notas | H5: No. | I5: Area | J5: Encargado
B6: CAP | C6: Capacitaciones | D6: CAPACITAR | E6: 0.2 | F6: Promedio Quincena 1 y Quincena 2 de % personal capacitado (aprobado con 100 pts) | H6: 1 | I6: Calidad | J6: Alejandro Martinez
B7: AE1 | C7: Auto Evaluacion 1 | D7: INSPECCIONAR | E7: 0.08 | F7: Correctas / Total preguntas checklist. 0 si no se realizo en semana asignada | H7: 2 | I7: Almacen de Repuestos | J7: Fredy Fuentes
B8: AE2 | C8: Auto Evaluacion 2 | D8: INSPECCIONAR | E8: 0.08 | F8: Correctas / Total preguntas checklist. 0 si no se realizo en semana asignada | H8: 3 | I8: Linea 4 | J8: Mario Ramos
B9: AE3 | C9: Auto Evaluacion 3 | D9: INSPECCIONAR | E9: 0.08 | F9: Correctas / Total preguntas checklist. 0 si no se realizo en semana asignada | H9: 4 | I9: Linea 5 | J9: Roy Luarca
B10: CRZ4 | C10: Cruzada 4 | D10: INSPECCIONAR | E10: 0.06 | F10: Correctas / Total preguntas. Si NO se realizo: penalizacion de 10% va al resultado FINAL del area | H10: 5 | I10: Linea 2 | J10: Amilcar Ralda
B11: ISSO | C11: Inspeccion SSO | D11: INSPECCIONAR | E11: 0.25 | F11: % resultado de Checklist de Integracion SSO (1 vez al mes) | H11: 6 | I11: Equipos Auxiliares | J11: Edson Bonifacio
B12: ACC | C12: Acciones Correctivas / Preventivas | D12: ACCIONAR | E12: 0.25 | F12: MAX(0%, Peso - 5% x No. acciones vencidas en Planner al cierre de mes). Piso en 0% | H12: 7 | I12: Linea 1 | J12: Amilcar Ralda
C13: TOTAL | E13: =SUM(E6:E12) -> 1 | H13: 8 | I13: ETEI | J13: Jessica Loarca
C14: Verificacion: | E14: =IF(E13=100%,"OK","REVISAR") -> OK | H14: 9 | I14: Centro de Distribucion | J14: Jimmy Velasquez
H15: 10 | I15: Jarabes | J15: Adrian Santisteban
B16: Parametros de Penalizacion | H16: 11 | I16: Linea 3 | J16: Mario Ramos
C17: Penalizacion si Cruzada 4 NO se realiza (sobre resultado final) | E17: 0.1 | H17: 12 | I17: Alrededores | J17: Carlos Chavez
C18: Penalizacion por cada accion vencida (Planner) | E18: 0.05 | H18: 13 | I18: Tratamiento de Aguas | J18: Adrian Santisteban
C19: Nota minima de evaluacion para contar como 'capacitado' | E19: 100 | H19: 14 | I19: Mantenimiento | J19: Eliu Tello
H20: 15 | I20: Materias Primas | J20: Miguel Godinez
B21: Parametros de Cultura (Bonificacion)
C22: Meta minima de Actos Inseguros validados por SSO (mensual) | E22: 8
C23: Meta minima de Condiciones Inseguras validadas por SSO (mensual) | E23: 10
C24: Bonificacion si se cumple meta de Actos | E24: 0.04
C25: Bonificacion si se cumple meta de Condiciones | E25: 0.04
B27: Parametros de Accidentabilidad (Penalizacion)
C28: Penalizacion por cada Incidente | E28: 0.05
C29: Penalizacion por cada FAI (Primeros Auxilios) | E29: 0.1
C30: Penalizacion por cada MTI (Tratamiento Medico) | E30: 0.15
C31: Penalizacion por cada MDI (Incapacidad Temporal/Dias Perdidos) | E31: 0.25
C32: Penalizacion por cada LTI (Incapacitante) | E32: 1
C33: Penalizacion si algun evento NO fue reportado a tiempo | E33: 1
B35: Rangos de Semaforo
B36: Nivel | C36: Desde | D36: Hasta | E36: Color
B37: Verde | C37: 0.9 | D37: 1.5
B38: Amarillo | C38: 0.7 | D38: 0.8999
B39: Rojo | C39: -1 | D39: 0.6999

Sheet Captura Enero
A1: CAPTURA DE DATOS - ENERO | AS1: TABLERO NIVEL DE SEGURIDAD — ENERO 2026 | BB1: CULTURA — ENERO 2026
A2: Mes / Periodo: | B2: Enero 2026 | F2: Instrucciones: | G2: Llenar SOLO las celdas en amarillo/azul. Las columnas de % y Nota se calculan automaticamente. Marcar 'NO' en las columnas de '¿Se realizo?' cuando una auto-evaluacion/cruzada no se hizo en su semana asignada. | AT2: CONTROLAR | AW2: CAPACITAR | AX2: CUIDAR | BB2: Tipo | BC2: Total mes
AS3: Área | AT3: Auto Evaluaciones (AE1+AE2+AE3) | AU3: Evaluación Cruzada | AV3: Inspección SSO | AW3: Capacita- ciones | AX3: Acciones Correctivas | AY3: Actos y Condiciones | AZ3: Accidenta- bilidad | BA3: Nivel de Seguridad | BB3: 🔶 Actos Inseguros | BC3: 48
D4: CAPACITACIONES (20%) | H4: AUTO EVALUACION 1 (8%) | L4: AUTO EVALUACION 2 (8%) | O4: AUTO EVALUACION 3 (8%) | R4: CRUZADA 4 (6%) | U4: INSPECCION SSO (25%) | W4: ACCIONES CORRECTIVAS/PREVENTIVAS (25%) | Y4: CULTURA (Bonificacion +8% max) | AD4: ACCIDENTABILIDAD (Penalizacion) | AP4: RESULTADO | AS4: ='Captura Enero'!B6 -> Almacen de Repuestos | AT4: ='Captura Enero'!K6+'Captura Enero'!N6+'Captura Enero'!Q6 -> 0.24 | AU4: ='Captura Enero'!T6 -> 0.06 | AV4: ='Captura Enero'!V6 -> 0.25 | AW4: ='Captura Enero'!G6 -> 0.2 | AX4: ='Captura Enero'!X6 -> 0.25 | AY4: ='Captura Enero'!AC6 -> 0 | AZ4: =-'Captura Enero'!AN6 -> 0 | BA4: ='Captura Enero'!AQ6 -> 1 | BB4: 🔷 Condiciones Inseguras | BC4: 280
A5: No. | B5: Area | C5: Encargado | D5: % Quincena 1 (input) | E5: % Quincena 2 (input) | F5: Promedio (auto) | G5: Nota Categoria (auto) | H5: Correctas | I5: Total Preguntas | J5: ¿Se realizo? | K5: Nota Categoria (auto) | L5: % Cumplimiento (input) | M5: ¿Se realizo? | N5: Nota Categoria (auto) | O5: % Cumplimiento (input) | P5: ¿Se realizo? | Q5: Nota Categoria (auto) | R5: % Cumplimiento (input) | S5: ¿Se realizo? | T5: Nota Categoria (auto) | U5: % Resultado Checklist | V5: Nota Categoria (auto) | W5: No. Acciones Vencidas | X5: Nota Categoria (auto) | Y5: Actos Validados | Z5: Condiciones Validadas | AA5: Bono Actos (auto) | AB5: Bono Cond. (auto) | AC5: Bono Total (auto) | AD5: Incidentes (No.) | AE5: Incid. ¿Reportado? | AF5: FAI (No.) | AG5: FAI ¿Reportado? | AH5: MTI (No.) | AI5: MTI ¿Reportado? | AJ5: MDI (No.) | AK5: MDI ¿Reportado? | AL5: LTI (No.) | AM5: LTI ¿Reportado? | AN5: Penaliz. Total (auto) | AO5: ¿Sin reportar? (auto) | AP5: Subtotal (suma notas) | AQ5: Nivel de Seguridad Final (auto) | AS5: ='Captura Enero'!B7 -> Alrededores | AT5: ='Captura Enero'!K7+'Captura Enero'!N7+'Captura Enero'!Q7 -> 0.24 | AU5: ='Captura Enero'!T7 -> 0.06 | AV5: ='Captura Enero'!V7 -> 0.25 | AW5: ='Captura Enero'!G7 -> 0.2 | AX5: ='Captura Enero'!X7 -> 0.15 | AY5: ='Captura Enero'!AC7 -> 0.04 | AZ5: =-'Captura Enero'!AN7 -> 0 | BA5: ='Captura Enero'!AQ7 -> 0.94 | BB5: ↑ Ingresa el total del mes en celdas amarillas
A6: 1 | B6: Almacen de Repuestos | C6: =VLOOKUP(B6,Parametros!$I$6:$J$20,2,FALSE()) -> Fredy Fuentes | D6: 1 | E6: 1 | F6: =AVERAGE(D6,E6) -> 1 | G6: =F6*Parametros!$E$6 -> 0.2 | H6: 10 | I6: 10 | J6: SI | K6: =IF(J6="NO",0,IFERROR(H6/I6,0)*Parametros!$E$7) -> 0.08 | L6: 1 | M6: SI | N6: =IF(M6="NO",0,L6*Parametros!$E$8) -> 0.08 | O6: 1 | P6: SI | Q6: =IF(P6="NO",0,O6*Parametros!$E$9) -> 0.08 | R6: 1 | S6: SI | T6: =IF(S6="NO",0,R6*Parametros!$E$10) -> 0.06 | U6: 1 | V6: =U6*Parametros!$E$11 -> 0.25 | W6: 0 | X6: =MAX(0,Parametros!$E$12-Parametros!$E$18*W6) -> 0.25 | Y6: 5 | Z6: 2 | AA6: =IF(Y6>=Parametros!$E$22,Parametros!$E$24,0) -> 0 | AB6: =IF(Z6>=Parametros!$E$23,Parametros!$E$25,0) -> 0 | AC6: =AA6+AB6 -> 0 | AD6: 0 | AE6: SI | AF6: 0 | AG6: SI | AH6: 0 | AI6: SI | AJ6: 0 | AK6: SI | AL6: 0 | AM6: SI | AN6: =AD6*Parametros!$E$28+AF6*Parametros!$E$29+AH6*Parametros!$E$30+AJ6*Parametros!$E$31+AL6*Parametros!$E$32 -> 0 | AO6: =IF(OR(AND(AD6>0,AE6="NO"),AND(AF6>0,AG6="NO"),AND(AH6>0,AI6="NO"),AND(AJ6>0,AK6="NO"),AND(AL6>0,AM6="NO")),"SI","NO") -> NO | AP6: =G6+K6+N6+Q6+T6+V6+X6 -> 1 | AQ6: =MAX(0,MIN(1,MAX(0,AP6-IF(S6="NO",Parametros!$E$17,0))+AC6-AN6-IF(AO6="SI",Parametros!$E$33,0))) -> 1 | AS6: ='Captura Enero'!B8 -> Calidad | AT6: ='Captura Enero'!K8+'Captura Enero'!N8+'Captura Enero'!Q8 -> 0.24 | AU6: ='Captura Enero'!T8 -> 0.06 | AV6: ='Captura Enero'!V8 -> 0.25 | AW6: ='Captura Enero'!G8 -> 0.2 | AX6: ='Captura Enero'!X8 -> 0.25 | AY6: ='Captura Enero'!AC8 -> 0.08 | AZ6: =-'Captura Enero'!AN8 -> 0 | BA6: ='Captura Enero'!AQ8 -> 1
A7: 2 | B7: Alrededores | C7: =VLOOKUP(B7,Parametros!$I$6:$J$20,2,FALSE()) -> Carlos Chavez | D7: 1 | E7: 1 | F7: =AVERAGE(D7,E7) -> 1 | G7: =F7*Parametros!$E$6 -> 0.2 | H7: 10 | I7: 10 | J7: SI | K7: =IF(J7="NO",0,IFERROR(H7/I7,0)*Parametros!$E$7) -> 0.08 | L7: 1 | M7: SI | N7: =IF(M7="NO",0,L7*Parametros!$E$8) -> 0.08 | O7: 1 | P7: SI | Q7: =IF(P7="NO",0,O7*Parametros!$E$9) -> 0.08 | R7: 1 | S7: SI | T7: =IF(S7="NO",0,R7*Parametros!$E$10) -> 0.06 | U7: 1 | V7: =U7*Parametros!$E$11 -> 0.25 | W7: 2 | X7: =MAX(0,Parametros!$E$12-Parametros!$E$18*W7) -> 0.15 | Y7: 0 | Z7: 13 | AA7: =IF(Y7>=Parametros!$E$22,Parametros!$E$24,0) -> 0 | AB7: =IF(Z7>=Parametros!$E$23,Parametros!$E$25,0) -> 0.04 | AC7: =AA7+AB7 -> 0.04 | AD7: 0 | AE7: SI | AF7: 0 | AG7: SI | AH7: 0 | AI7: SI | AJ7: 0 | AK7: SI | AL7: 0 | AM7: SI | AN7: =AD7*Parametros!$E$28+AF7*Parametros!$E$29+AH7*Parametros!$E$30+AJ7*Parametros!$E$31+AL7*Parametros!$E$32 -> 0 | AO7: =IF(OR(AND(AD7>0,AE7="NO"),AND(AF7>0,AG7="NO"),AND(AH7>0,AI7="NO"),AND(AJ7>0,AK7="NO"),AND(AL7>0,AM7="NO")),"SI","NO") -> NO | AP7: =G7+K7+N7+Q7+T7+V7+X7 -> 0.9 | AQ7: =MAX(0,MIN(1,MAX(0,AP7-IF(S7="NO",Parametros!$E$17,0))+AC7-AN7-IF(AO7="SI",Parametros!$E$33,0))) -> 0.94 | AS7: ='Captura Enero'!B9 -> Centro de Distribucion | AT7: ='Captura Enero'!K9+'Captura Enero'!N9+'Captura Enero'!Q9 -> 0.24 | AU7: ='Captura Enero'!T9 -> 0.06 | AV7: ='Captura Enero'!V9 -> 0.25 | AW7: ='Captura Enero'!G9 -> 0.1974359 | AX7: ='Captura Enero'!X9 -> 0.25 | AY7: ='Captura Enero'!AC9 -> 0.04 | AZ7: =-'Captura Enero'!AN9 -> 0 | BA7: ='Captura Enero'!AQ9 -> 1
A8: 3 | B8: Calidad | C8: =VLOOKUP(B8,Parametros!$I$6:$J$20,2,FALSE()) -> Alejandro Martinez | D8: 1 | E8: 1 | F8: =AVERAGE(D8,E8) -> 1 | G8: =F8*Parametros!$E$6 -> 0.2 | H8: 10 | I8: 10 | J8: SI | K8: =IF(J8="NO",0,IFERROR(H8/I8,0)*Parametros!$E$7) -> 0.08 | L8: 1 | M8: SI | N8: =IF(M8="NO",0,L8*Parametros!$E$8) -> 0.08 | O8: 1 | P8: SI | Q8: =IF(P8="NO",0,O8*Parametros!$E$9) -> 0.08 | R8: 1 | S8: SI | T8: =IF(S8="NO",0,R8*Parametros!$E$10) -> 0.06 | U8: 1 | V8: =U8*Parametros!$E$11 -> 0.25 | W8: 0 | X8: =MAX(0,Parametros!$E$12-Parametros!$E$18*W8) -> 0.25 | Y8: 9 | Z8: 34 | AA8: =IF(Y8>=Parametros!$E$22,Parametros!$E$24,0) -> 0.04 | AB8: =IF(Z8>=Parametros!$E$23,Parametros!$E$25,0) -> 0.04 | AC8: =AA8+AB8 -> 0.08 | AD8: 0 | AE8: SI | AF8: 0 | AG8: SI | AH8: 0 | AI8: SI | AJ8: 0 | AK8: SI | AL8: 0 | AM8: SI | AN8: =AD8*Parametros!$E$28+AF8*Parametros!$E$29+AH8*Parametros!$E$30+AJ8*Parametros!$E$31+AL8*Parametros!$E$32 -> 0 | AO8: =IF(OR(AND(AD8>0,AE8="NO"),AND(AF8>0,AG8="NO"),AND(AH8>0,AI8="NO"),AND(AJ8>0,AK8="NO"),AND(AL8>0,AM8="NO")),"SI","NO") -> NO | AP8: =G8+K8+N8+Q8+T8+V8+X8 -> 1 | AQ8: =MAX(0,MIN(1,MAX(0,AP8-IF(S8="NO",Parametros!$E$17,0))+AC8-AN8-IF(AO8="SI",Parametros!$E$33,0))) -> 1 | AS8: ='Captura Enero'!B10 -> ETEI | AT8: ='Captura Enero'!K10+'Captura Enero'!N10+'Captura Enero'!Q10 -> 0.24 | AU8: ='Captura Enero'!T10 -> 0.06 | AV8: ='Captura Enero'!V10 -> 0.25 | AW8: ='Captura Enero'!G10 -> 0.15 | AX8: ='Captura Enero'!X10 -> 0.25 | AY8: ='Captura Enero'!AC10 -> 0 | AZ8: =-'Captura Enero'!AN10 -> 0 | BA8: ='Captura Enero'!AQ10 -> 0.95
A9: 4 | B9: Centro de Distribucion | C9: =VLOOKUP(B9,Parametros!$I$6:$J$20,2,FALSE()) -> Jimmy Velasquez | D9: 0.97435897 | E9: 1 | F9: =AVERAGE(D9,E9) -> 0.98717949 | G9: =F9*Parametros!$E$6 -> 0.1974359 | H9: 10 | I9: 10 | J9: SI | K9: =IF(J9="NO",0,IFERROR(H9/I9,0)*Parametros!$E$7) -> 0.08 | L9: 1 | M9: SI | N9: =IF(M9="NO",0,L9*Parametros!$E$8) -> 0.08 | O9: 1 | P9: SI | Q9: =IF(P9="NO",0,O9*Parametros!$E$9) -> 0.08 | R9: 1 | S9: SI | T9: =IF(S9="NO",0,R9*Parametros!$E$10) -> 0.06 | U9: 1 | V9: =U9*Parametros!$E$11 -> 0.25 | W9: 0 | X9: =MAX(0,Parametros!$E$12-Parametros!$E$18*W9) -> 0.25 | Y9: 5 | Z9: 21 | AA9: =IF(Y9>=Parametros!$E$22,Parametros!$E$24,0) -> 0 | AB9: =IF(Z9>=Parametros!$E$23,Parametros!$E$25,0) -> 0.04 | AC9: =AA9+AB9 -> 0.04 | AD9: 0 | AE9: SI | AF9: 0 | AG9: SI | AH9: 0 | AI9: SI | AJ9: 0 | AK9: SI | AL9: 0 | AM9: SI | AN9: =AD9*Parametros!$E$28+AF9*Parametros!$E$29+AH9*Parametros!$E$30+AJ9*Parametros!$E$31+AL9*Parametros!$E$32 -> 0 | AO9: =IF(OR(AND(AD9>0,AE9="NO"),AND(AF9>0,AG9="NO"),AND(AH9>0,AI9="NO"),AND(AJ9>0,AK9="NO"),AND(AL9>0,AM9="NO")),"SI","NO") -> NO | AP9: =G9+K9+N9+Q9+T9+V9+X9 -> 0.9974359 | AQ9: =MAX(0,MIN(1,MAX(0,AP9-IF(S9="NO",Parametros!$E$17,0))+AC9-AN9-IF(AO9="SI",Parametros!$E$33,0))) -> 1 | AS9: ='Captura Enero'!B11 -> Equipos Auxiliares | AT9: ='Captura Enero'!K11+'Captura Enero'!N11+'Captura Enero'!Q11 -> 0.24 | AU9: ='Captura Enero'!T11 -> 0 | AV9: ='Captura Enero'!V11 -> 0.25 | AW9: ='Captura Enero'!G11 -> 0.2 | AX9: ='Captura Enero'!X11 -> 0.25 | AY9: ='Captura Enero'!AC11 -> 0 | AZ9: =-'Captura Enero'!AN11 -> 0 | BA9: ='Captura Enero'!AQ11 -> 0.84
A10: 5 | B10: ETEI | C10: =VLOOKUP(B10,Parametros!$I$6:$J$20,2,FALSE()) -> Jessica Loarca | D10: 1 | E10: 0.5 | F10: =AVERAGE(D10,E10) -> 0.75 | G10: =F10*Parametros!$E$6 -> 0.15 | H10: 10 | I10: 10 | J10: SI | K10: =IF(J10="NO",0,IFERROR(H10/I10,0)*Parametros!$E$7) -> 0.08 | L10: 1 | M10: SI | N10: =IF(M10="NO",0,L10*Parametros!$E$8) -> 0.08 | O10: 1 | P10: SI | Q10: =IF(P10="NO",0,O10*Parametros!$E$9) -> 0.08 | R10: 1 | S10: SI | T10: =IF(S10="NO",0,R10*Parametros!$E$10) -> 0.06 | U10: 1 | V10: =U10*Parametros!$E$11 -> 0.25 | W10: 0 | X10: =MAX(0,Parametros!$E$12-Parametros!$E$18*W10) -> 0.25 | Y10: 0 | Z10: 7 | AA10: =IF(Y10>=Parametros!$E$22,Parametros!$E$24,0) -> 0 | AB10: =IF(Z10>=Parametros!$E$23,Parametros!$E$25,0) -> 0 | AC10: =AA10+AB10 -> 0 | AD10: 0 | AE10: SI | AF10: 0 | AG10: SI | AH10: 0 | AI10: SI | AJ10: 0 | AK10: SI | AL10: 0 | AM10: SI | AN10: =AD10*Parametros!$E$28+AF10*Parametros!$E$29+AH10*Parametros!$E$30+AJ10*Parametros!$E$31+AL10*Parametros!$E$32 -> 0 | AO10: =IF(OR(AND(AD10>0,AE10="NO"),AND(AF10>0,AG10="NO"),AND(AH10>0,AI10="NO"),AND(AJ10>0,AK10="NO"),AND(AL10>0,AM10="NO")),"SI","NO") -> NO | AP10: =G10+K10+N10+Q10+T10+V10+X10 -> 0.95 | AQ10: =MAX(0,MIN(1,MAX(0,AP10-IF(S10="NO",Parametros!$E$17,0))+AC10-AN10-IF(AO10="SI",Parametros!$E$33,0))) -> 0.95 | AS10: ='Captura Enero'!B12 -> Jarabes | AT10: ='Captura Enero'!K12+'Captura Enero'!N12+'Captura Enero'!Q12 -> 0.24 | AU10: ='Captura Enero'!T12 -> 0.06 | AV10: ='Captura Enero'!V12 -> 0.25 | AW10: ='Captura Enero'!G12 -> 0.2 | AX10: ='Captura Enero'!X12 -> 0 | AY10: ='Captura Enero'!AC12 -> 0.04 | AZ10: =-'Captura Enero'!AN12 -> 0 | BA10: ='Captura Enero'!AQ12 -> 0.79
A11: 6 | B11: Equipos Auxiliares | C11: =VLOOKUP(B11,Parametros!$I$6:$J$20,2,FALSE()) -> Edson Bonifacio | D11: 1 | E11: 1 | F11: =AVERAGE(D11,E11) -> 1 | G11: =F11*Parametros!$E$6 -> 0.2 | H11: 10 | I11: 10 | J11: SI | K11: =IF(J11="NO",0,IFERROR(H11/I11,0)*Parametros!$E$7) -> 0.08 | L11: 1 | M11: SI | N11: =IF(M11="NO",0,L11*Parametros!$E$8) -> 0.08 | O11: 1 | P11: SI | Q11: =IF(P11="NO",0,O11*Parametros!$E$9) -> 0.08 | R11: 0 | S11: NO | T11: =IF(S11="NO",0,R11*Parametros!$E$10) -> 0 | U11: 1 | V11: =U11*Parametros!$E$11 -> 0.25 | W11: 0 | X11: =MAX(0,Parametros!$E$12-Parametros!$E$18*W11) -> 0.25 | Y11: 3 | Z11: 9 | AA11: =IF(Y11>=Parametros!$E$22,Parametros!$E$24,0) -> 0 | AB11: =IF(Z11>=Parametros!$E$23,Parametros!$E$25,0) -> 0 | AC11: =AA11+AB11 -> 0 | AD11: 0 | AE11: SI | AF11: 0 | AG11: SI | AH11: 0 | AI11: SI | AJ11: 0 | AK11: SI | AL11: 0 | AM11: SI | AN11: =AD11*Parametros!$E$28+AF11*Parametros!$E$29+AH11*Parametros!$E$30+AJ11*Parametros!$E$31+AL11*Parametros!$E$32 -> 0 | AO11: =IF(OR(AND(AD11>0,AE11="NO"),AND(AF11>0,AG11="NO"),AND(AH11>0,AI11="NO"),AND(AJ11>0,AK11="NO"),AND(AL11>0,AM11="NO")),"SI","NO") -> NO | AP11: =G11+K11+N11+Q11+T11+V11+X11 -> 0.94 | AQ11: =MAX(0,MIN(1,MAX(0,AP11-IF(S11="NO",Parametros!$E$17,0))+AC11-AN11-IF(AO11="SI",Parametros!$E$33,0))) -> 0.84 | AS11: ='Captura Enero'!B13 -> Linea 1 | AT11: ='Captura Enero'!K13+'Captura Enero'!N13+'Captura Enero'!Q13 -> 0.24 | AU11: ='Captura Enero'!T13 -> 0.06 | AV11: ='Captura Enero'!V13 -> 0.25 | AW11: ='Captura Enero'!G13 -> 0.2 | AX11: ='Captura Enero'!X13 -> 0.25 | AY11: ='Captura Enero'!AC13 -> 0.04 | AZ11: =-'Captura Enero'!AN13 -> -0.05 | BA11: ='Captura Enero'!AQ13 -> 0.99
A12: 7 | B12: Jarabes | C12: =VLOOKUP(B12,Parametros!$I$6:$J$20,2,FALSE()) -> Adrian Santisteban | D12: 1 | E12: 1 | F12: =AVERAGE(D12,E12) -> 1 | G12: =F12*Parametros!$E$6 -> 0.2 | H12: 10 | I12: 10 | J12: SI | K12: =IF(J12="NO",0,IFERROR(H12/I12,0)*Parametros!$E$7) -> 0.08 | L12: 1 | M12: SI | N12: =IF(M12="NO",0,L12*Parametros!$E$8) -> 0.08 | O12: 1 | P12: SI | Q12: =IF(P12="NO",0,O12*Parametros!$E$9) -> 0.08 | R12: 1 | S12: SI | T12: =IF(S12="NO",0,R12*Parametros!$E$10) -> 0.06 | U12: 1 | V12: =U12*Parametros!$E$11 -> 0.25 | W12: 6 | X12: =MAX(0,Parametros!$E$12-Parametros!$E$18*W12) -> 0 | Y12: 4 | Z12: 11 | AA12: =IF(Y12>=Parametros!$E$22,Parametros!$E$24,0) -> 0 | AB12: =IF(Z12>=Parametros!$E$23,Parametros!$E$25,0) -> 0.04 | AC12: =AA12+AB12 -> 0.04 | AD12: 0 | AE12: SI | AF12: 0 | AG12: SI | AH12: 0 | AI12: SI | AJ12: 0 | AK12: SI | AL12: 0 | AM12: SI | AN12: =AD12*Parametros!$E$28+AF12*Parametros!$E$29+AH12*Parametros!$E$30+AJ12*Parametros!$E$31+AL12*Parametros!$E$32 -> 0 | AO12: =IF(OR(AND(AD12>0,AE12="NO"),AND(AF12>0,AG12="NO"),AND(AH12>0,AI12="NO"),AND(AJ12>0,AK12="NO"),AND(AL12>0,AM12="NO")),"SI","NO") -> NO | AP12: =G12+K12+N12+Q12+T12+V12+X12 -> 0.75 | AQ12: =MAX(0,MIN(1,MAX(0,AP12-IF(S12="NO",Parametros!$E$17,0))+AC12-AN12-IF(AO12="SI",Parametros!$E$33,0))) -> 0.79 | AS12: ='Captura Enero'!B14 -> Linea 2 | AT12: ='Captura Enero'!K14+'Captura Enero'!N14+'Captura Enero'!Q14 -> 0.24 | AU12: ='Captura Enero'!T14 -> 0.06 | AV12: ='Captura Enero'!V14 -> 0.25 | AW12: ='Captura Enero'!G14 -> 0.2 | AX12: ='Captura Enero'!X14 -> 0.2 | AY12: ='Captura Enero'!AC14 -> 0.04 | AZ12: =-'Captura Enero'!AN14 -> 0 | BA12: ='Captura Enero'!AQ14 -> 0.99
A13: 8 | B13: Linea 1 | C13: =VLOOKUP(B13,Parametros!$I$6:$J$20,2,FALSE()) -> Amilcar Ralda | D13: 1 | E13: 1 | F13: =AVERAGE(D13,E13) -> 1 | G13: =F13*Parametros!$E$6 -> 0.2 | H13: 10 | I13: 10 | J13: SI | K13: =IF(J13="NO",0,IFERROR(H13/I13,0)*Parametros!$E$7) -> 0.08 | L13: 1 | M13: SI | N13: =IF(M13="NO",0,L13*Parametros!$E$8) -> 0.08 | O13: 1 | P13: SI | Q13: =IF(P13="NO",0,O13*Parametros!$E$9) -> 0.08 | R13: 1 | S13: SI | T13: =IF(S13="NO",0,R13*Parametros!$E$10) -> 0.06 | U13: 1 | V13: =U13*Parametros!$E$11 -> 0.25 | W13: 0 | X13: =MAX(0,Parametros!$E$12-Parametros!$E$18*W13) -> 0.25 | Y13: 4 | Z13: 21 | AA13: =IF(Y13>=Parametros!$E$22,Parametros!$E$24,0) -> 0 | AB13: =IF(Z13>=Parametros!$E$23,Parametros!$E$25,0) -> 0.04 | AC13: =AA13+AB13 -> 0.04 | AD13: 1 | AE13: SI | AF13: 0 | AG13: SI | AH13: 0 | AI13: SI | AJ13: 0 | AK13: SI | AL13: 0 | AM13: SI | AN13: =AD13*Parametros!$E$28+AF13*Parametros!$E$29+AH13*Parametros!$E$30+AJ13*Parametros!$E$31+AL13*Parametros!$E$32 -> 0.05 | AO13: =IF(OR(AND(AD13>0,AE13="NO"),AND(AF13>0,AG13="NO"),AND(AH13>0,AI13="NO"),AND(AJ13>0,AK13="NO"),AND(AL13>0,AM13="NO")),"SI","NO") -> NO | AP13: =G13+K13+N13+Q13+T13+V13+X13 -> 1 | AQ13: =MAX(0,MIN(1,MAX(0,AP13-IF(S13="NO",Parametros!$E$17,0))+AC13-AN13-IF(AO13="SI",Parametros!$E$33,0))) -> 0.99 | AS13: ='Captura Enero'!B15 -> Linea 3 | AT13: ='Captura Enero'!K15+'Captura Enero'!N15+'Captura Enero'!Q15 -> 0.24 | AU13: ='Captura Enero'!T15 -> 0.06 | AV13: ='Captura Enero'!V15 -> 0.25 | AW13: ='Captura Enero'!G15 -> 0.2 | AX13: ='Captura Enero'!X15 -> 0.15 | AY13: ='Captura Enero'!AC15 -> 0.04 | AZ13: =-'Captura Enero'!AN15 -> 0 | BA13: ='Captura Enero'!AQ15 -> 0.94
A14: 9 | B14: Linea 2 | C14: =VLOOKUP(B14,Parametros!$I$6:$J$20,2,FALSE()) -> Amilcar Ralda | D14: 1 | E14: 1 | F14: =AVERAGE(D14,E14) -> 1 | G14: =F14*Parametros!$E$6 -> 0.2 | H14: 10 | I14: 10 | J14: SI | K14: =IF(J14="NO",0,IFERROR(H14/I14,0)*Parametros!$E$7) -> 0.08 | L14: 1 | M14: SI | N14: =IF(M14="NO",0,L14*Parametros!$E$8) -> 0.08 | O14: 1 | P14: SI | Q14: =IF(P14="NO",0,O14*Parametros!$E$9) -> 0.08 | R14: 1 | S14: SI | T14: =IF(S14="NO",0,R14*Parametros!$E$10) -> 0.06 | U14: 1 | V14: =U14*Parametros!$E$11 -> 0.25 | W14: 1 | X14: =MAX(0,Parametros!$E$12-Parametros!$E$18*W14) -> 0.2 | Y14: 4 | Z14: 12 | AA14: =IF(Y14>=Parametros!$E$22,Parametros!$E$24,0) -> 0 | AB14: =IF(Z14>=Parametros!$E$23,Parametros!$E$25,0) -> 0.04 | AC14: =AA14+AB14 -> 0.04 | AD14: 0 | AE14: SI | AF14: 0 | AG14: SI | AH14: 0 | AI14: SI | AJ14: 0 | AK14: SI | AL14: 0 | AM14: SI | AN14: =AD14*Parametros!$E$28+AF14*Parametros!$E$29+AH14*Parametros!$E$30+AJ14*Parametros!$E$31+AL14*Parametros!$E$32 -> 0 | AO14: =IF(OR(AND(AD14>0,AE14="NO"),AND(AF14>0,AG14="NO"),AND(AH14>0,AI14="NO"),AND(AJ14>0,AK14="NO"),AND(AL14>0,AM14="NO")),"SI","NO") -> NO | AP14: =G14+K14+N14+Q14+T14+V14+X14 -> 0.95 | AQ14: =MAX(0,MIN(1,MAX(0,AP14-IF(S14="NO",Parametros!$E$17,0))+AC14-AN14-IF(AO14="SI",Parametros!$E$33,0))) -> 0.99 | AS14: ='Captura Enero'!B16 -> Linea 4 | AT14: ='Captura Enero'!K16+'Captura Enero'!N16+'Captura Enero'!Q16 -> 0.24 | AU14: ='Captura Enero'!T16 -> 0.06 | AV14: ='Captura Enero'!V16 -> 0.25 | AW14: ='Captura Enero'!G16 -> 0.2 | AX14: ='Captura Enero'!X16 -> 0.15 | AY14: ='Captura Enero'!AC16 -> 0 | AZ14: =-'Captura Enero'!AN16 -> 0 | BA14: ='Captura Enero'!AQ16 -> 0.9
A15: 10 | B15: Linea 3 | C15: =VLOOKUP(B15,Parametros!$I$6:$J$20,2,FALSE()) -> Mario Ramos | D15: 1 | E15: 1 | F15: =AVERAGE(D15,E15) -> 1 | G15: =F15*Parametros!$E$6 -> 0.2 | H15: 10 | I15: 10 | J15: SI | K15: =IF(J15="NO",0,IFERROR(H15/I15,0)*Parametros!$E$7) -> 0.08 | L15: 1 | M15: SI | N15: =IF(M15="NO",0,L15*Parametros!$E$8) -> 0.08 | O15: 1 | P15: SI | Q15: =IF(P15="NO",0,O15*Parametros!$E$9) -> 0.08 | R15: 1 | S15: SI | T15: =IF(S15="NO",0,R15*Parametros!$E$10) -> 0.06 | U15: 1 | V15: =U15*Parametros!$E$11 -> 0.25 | W15: 2 | X15: =MAX(0,Parametros!$E$12-Parametros!$E$18*W15) -> 0.15 | Y15: 4 | Z15: 12 | AA15: =IF(Y15>=Parametros!$E$22,Parametros!$E$24,0) -> 0 | AB15: =IF(Z15>=Parametros!$E$23,Parametros!$E$25,0) -> 0.04 | AC15: =AA15+AB15 -> 0.04 | AD15: 0 | AE15: SI | AF15: 0 | AG15: SI | AH15: 0 | AI15: SI | AJ15: 0 | AK15: SI | AL15: 0 | AM15: SI | AN15: =AD15*Parametros!$E$28+AF15*Parametros!$E$29+AH15*Parametros!$E$30+AJ15*Parametros!$E$31+AL15*Parametros!$E$32 -> 0 | AO15: =IF(OR(AND(AD15>0,AE15="NO"),AND(AF15>0,AG15="NO"),AND(AH15>0,AI15="NO"),AND(AJ15>0,AK15="NO"),AND(AL15>0,AM15="NO")),"SI","NO") -> NO | AP15: =G15+K15+N15+Q15+T15+V15+X15 -> 0.9 | AQ15: =MAX(0,MIN(1,MAX(0,AP15-IF(S15="NO",Parametros!$E$17,0))+AC15-AN15-IF(AO15="SI",Parametros!$E$33,0))) -> 0.94 | AS15: ='Captura Enero'!B17 -> Linea 5 | AT15: ='Captura Enero'!K17+'Captura Enero'!N17+'Captura Enero'!Q17 -> 0.24 | AU15: ='Captura Enero'!T17 -> 0 | AV15: ='Captura Enero'!V17 -> 0.25 | AW15: ='Captura Enero'!G17 -> 0.18461538 | AX15: ='Captura Enero'!X17 -> 0.25 | AY15: ='Captura Enero'!AC17 -> 0.04 | AZ15: =-'Captura Enero'!AN17 -> 0 | BA15: ='Captura Enero'!AQ17 -> 0.86461538
A16: 11 | B16: Linea 4 | C16: =VLOOKUP(B16,Parametros!$I$6:$J$20,2,FALSE()) -> Mario Ramos | D16: 1 | E16: 1 | F16: =AVERAGE(D16,E16) -> 1 | G16: =F16*Parametros!$E$6 -> 0.2 | H16: 10 | I16: 10 | J16: SI | K16: =IF(J16="NO",0,IFERROR(H16/I16,0)*Parametros!$E$7) -> 0.08 | L16: 1 | M16: SI | N16: =IF(M16="NO",0,L16*Parametros!$E$8) -> 0.08 | O16: 1 | P16: SI | Q16: =IF(P16="NO",0,O16*Parametros!$E$9) -> 0.08 | R16: 1 | S16: SI | T16: =IF(S16="NO",0,R16*Parametros!$E$10) -> 0.06 | U16: 1 | V16: =U16*Parametros!$E$11 -> 0.25 | W16: 2 | X16: =MAX(0,Parametros!$E$12-Parametros!$E$18*W16) -> 0.15 | Y16: 2 | Z16: 5 | AA16: =IF(Y16>=Parametros!$E$22,Parametros!$E$24,0) -> 0 | AB16: =IF(Z16>=Parametros!$E$23,Parametros!$E$25,0) -> 0 | AC16: =AA16+AB16 -> 0 | AD16: 0 | AE16: SI | AF16: 0 | AG16: SI | AH16: 0 | AI16: SI | AJ16: 0 | AK16: SI | AL16: 0 | AM16: SI | AN16: =AD16*Parametros!$E$28+AF16*Parametros!$E$29+AH16*Parametros!$E$30+AJ16*Parametros!$E$31+AL16*Parametros!$E$32 -> 0 | AO16: =IF(OR(AND(AD16>0,AE16="NO"),AND(AF16>0,AG16="NO"),AND(AH16>0,AI16="NO"),AND(AJ16>0,AK16="NO"),AND(AL16>0,AM16="NO")),"SI","NO") -> NO | AP16: =G16+K16+N16+Q16+T16+V16+X16 -> 0.9 | AQ16: =MAX(0,MIN(1,MAX(0,AP16-IF(S16="NO",Parametros!$E$17,0))+AC16-AN16-IF(AO16="SI",Parametros!$E$33,0))) -> 0.9 | AS16: ='Captura Enero'!B18 -> Mantenimiento | AT16: ='Captura Enero'!K18+'Captura Enero'!N18+'Captura Enero'!Q18 -> 0.24 | AU16: ='Captura Enero'!T18 -> 0 | AV16: ='Captura Enero'!V18 -> 0.25 | AW16: ='Captura Enero'!G18 -> 0.2 | AX16: ='Captura Enero'!X18 -> 0.25 | AY16: ='Captura Enero'!AC18 -> 0 | AZ16: =-'Captura Enero'!AN18 -> 0 | BA16: ='Captura Enero'!AQ18 -> 0.84
A17: 12 | B17: Linea 5 | C17: =VLOOKUP(B17,Parametros!$I$6:$J$20,2,FALSE()) -> Roy Luarca | D17: 0.92307692 | E17: 0.92307692 | F17: =AVERAGE(D17,E17) -> 0.92307692 | G17: =F17*Parametros!$E$6 -> 0.18461538 | H17: 10 | I17: 10 | J17: SI | K17: =IF(J17="NO",0,IFERROR(H17/I17,0)*Parametros!$E$7) -> 0.08 | L17: 1 | M17: SI | N17: =IF(M17="NO",0,L17*Parametros!$E$8) -> 0.08 | O17: 1 | P17: SI | Q17: =IF(P17="NO",0,O17*Parametros!$E$9) -> 0.08 | R17: 0 | S17: NO | T17: =IF(S17="NO",0,R17*Parametros!$E$10) -> 0 | U17: 1 | V17: =U17*Parametros!$E$11 -> 0.25 | W17: 0 | X17: =MAX(0,Parametros!$E$12-Parametros!$E$18*W17) -> 0.25 | Y17: 5 | Z17: 11 | AA17: =IF(Y17>=Parametros!$E$22,Parametros!$E$24,0) -> 0 | AB17: =IF(Z17>=Parametros!$E$23,Parametros!$E$25,0) -> 0.04 | AC17: =AA17+AB17 -> 0.04 | AD17: 0 | AE17: SI | AF17: 0 | AG17: SI | AH17: 0 | AI17: SI | AJ17: 0 | AK17: SI | AL17: 0 | AM17: SI | AN17: =AD17*Parametros!$E$28+AF17*Parametros!$E$29+AH17*Parametros!$E$30+AJ17*Parametros!$E$31+AL17*Parametros!$E$32 -> 0 | AO17: =IF(OR(AND(AD17>0,AE17="NO"),AND(AF17>0,AG17="NO"),AND(AH17>0,AI17="NO"),AND(AJ17>0,AK17="NO"),AND(AL17>0,AM17="NO")),"SI","NO") -> NO | AP17: =G17+K17+N17+Q17+T17+V17+X17 -> 0.92461538 | AQ17: =MAX(0,MIN(1,MAX(0,AP17-IF(S17="NO",Parametros!$E$17,0))+AC17-AN17-IF(AO17="SI",Parametros!$E$33,0))) -> 0.86461538 | AS17: ='Captura Enero'!B19 -> Materias Primas | AT17: ='Captura Enero'!K19+'Captura Enero'!N19+'Captura Enero'!Q19 -> 0.24 | AU17: ='Captura Enero'!T19 -> 0.06 | AV17: ='Captura Enero'!V19 -> 0.25 | AW17: ='Captura Enero'!G19 -> 0.2 | AX17: ='Captura Enero'!X19 -> 0.25 | AY17: ='Captura Enero'!AC19 -> 0.04 | AZ17: =-'Captura Enero'!AN19 -> 0 | BA17: ='Captura Enero'!AQ19 -> 1
A18: 13 | B18: Mantenimiento | C18: =VLOOKUP(B18,Parametros!$I$6:$J$20,2,FALSE()) -> Eliu Tello | D18: 1 | E18: 1 | F18: =AVERAGE(D18,E18) -> 1 | G18: =F18*Parametros!$E$6 -> 0.2 | H18: 10 | I18: 10 | J18: SI | K18: =IF(J18="NO",0,IFERROR(H18/I18,0)*Parametros!$E$7) -> 0.08 | L18: 1 | M18: SI | N18: =IF(M18="NO",0,L18*Parametros!$E$8) -> 0.08 | O18: 1 | P18: SI | Q18: =IF(P18="NO",0,O18*Parametros!$E$9) -> 0.08 | R18: 0 | S18: NO | T18: =IF(S18="NO",0,R18*Parametros!$E$10) -> 0 | U18: 1 | V18: =U18*Parametros!$E$11 -> 0.25 | W18: 0 | X18: =MAX(0,Parametros!$E$12-Parametros!$E$18*W18) -> 0.25 | Y18: 1 | Z18: 9 | AA18: =IF(Y18>=Parametros!$E$22,Parametros!$E$24,0) -> 0 | AB18: =IF(Z18>=Parametros!$E$23,Parametros!$E$25,0) -> 0 | AC18: =AA18+AB18 -> 0 | AD18: 0 | AE18: SI | AF18: 0 | AG18: SI | AH18: 0 | AI18: SI | AJ18: 0 | AK18: SI | AL18: 0 | AM18: SI | AN18: =AD18*Parametros!$E$28+AF18*Parametros!$E$29+AH18*Parametros!$E$30+AJ18*Parametros!$E$31+AL18*Parametros!$E$32 -> 0 | AO18: =IF(OR(AND(AD18>0,AE18="NO"),AND(AF18>0,AG18="NO"),AND(AH18>0,AI18="NO"),AND(AJ18>0,AK18="NO"),AND(AL18>0,AM18="NO")),"SI","NO") -> NO | AP18: =G18+K18+N18+Q18+T18+V18+X18 -> 0.94 | AQ18: =MAX(0,MIN(1,MAX(0,AP18-IF(S18="NO",Parametros!$E$17,0))+AC18-AN18-IF(AO18="SI",Parametros!$E$33,0))) -> 0.84 | AS18: ='Captura Enero'!B20 -> Tratamiento de Aguas | AT18: ='Captura Enero'!K20+'Captura Enero'!N20+'Captura Enero'!Q20 -> 0.24 | AU18: ='Captura Enero'!T20 -> 0.06 | AV18: ='Captura Enero'!V20 -> 0.25 | AW18: ='Captura Enero'!G20 -> 0.2 | AX18: ='Captura Enero'!X20 -> 0.2 | AY18: ='Captura Enero'!AC20 -> 0 | AZ18: =-'Captura Enero'!AN20 -> 0 | BA18: ='Captura Enero'!AQ20 -> 0.95
A19: 14 | B19: Materias Primas | C19: =VLOOKUP(B19,Parametros!$I$6:$J$20,2,FALSE()) -> Miguel Godinez | D19: 1 | E19: 1 | F19: =AVERAGE(D19,E19) -> 1 | G19: =F19*Parametros!$E$6 -> 0.2 | H19: 10 | I19: 10 | J19: SI | K19: =IF(J19="NO",0,IFERROR(H19/I19,0)*Parametros!$E$7) -> 0.08 | L19: 1 | M19: SI | N19: =IF(M19="NO",0,L19*Parametros!$E$8) -> 0.08 | O19: 1 | P19: SI | Q19: =IF(P19="NO",0,O19*Parametros!$E$9) -> 0.08 | R19: 1 | S19: SI | T19: =IF(S19="NO",0,R19*Parametros!$E$10) -> 0.06 | U19: 1 | V19: =U19*Parametros!$E$11 -> 0.25 | W19: 0 | X19: =MAX(0,Parametros!$E$12-Parametros!$E$18*W19) -> 0.25 | Y19: 1 | Z19: 16 | AA19: =IF(Y19>=Parametros!$E$22,Parametros!$E$24,0) -> 0 | AB19: =IF(Z19>=Parametros!$E$23,Parametros!$E$25,0) -> 0.04 | AC19: =AA19+AB19 -> 0.04 | AD19: 0 | AE19: SI | AF19: 0 | AG19: SI | AH19: 0 | AI19: SI | AJ19: 0 | AK19: SI | AL19: 0 | AM19: SI | AN19: =AD19*Parametros!$E$28+AF19*Parametros!$E$29+AH19*Parametros!$E$30+AJ19*Parametros!$E$31+AL19*Parametros!$E$32 -> 0 | AO19: =IF(OR(AND(AD19>0,AE19="NO"),AND(AF19>0,AG19="NO"),AND(AH19>0,AI19="NO"),AND(AJ19>0,AK19="NO"),AND(AL19>0,AM19="NO")),"SI","NO") -> NO | AP19: =G19+K19+N19+Q19+T19+V19+X19 -> 1 | AQ19: =MAX(0,MIN(1,MAX(0,AP19-IF(S19="NO",Parametros!$E$17,0))+AC19-AN19-IF(AO19="SI",Parametros!$E$33,0))) -> 1 | AS19: Nivel de seguridad planta — Enero 2026 | BA19: =AVERAGE(BA4:BA18) -> 0.93297436
A20: 15 | B20: Tratamiento de Aguas | C20: =VLOOKUP(B20,Parametros!$I$6:$J$20,2,FALSE()) -> Adrian Santisteban | D20: 1 | E20: 1 | F20: =AVERAGE(D20,E20) -> 1 | G20: =F20*Parametros!$E$6 -> 0.2 | H20: 10 | I20: 10 | J20: SI | K20: =IF(J20="NO",0,IFERROR(H20/I20,0)*Parametros!$E$7) -> 0.08 | L20: 1 | M20: SI | N20: =IF(M20="NO",0,L20*Parametros!$E$8) -> 0.08 | O20: 1 | P20: SI | Q20: =IF(P20="NO",0,O20*Parametros!$E$9) -> 0.08 | R20: 1 | S20: SI | T20: =IF(S20="NO",0,R20*Parametros!$E$10) -> 0.06 | U20: 1 | V20: =U20*Parametros!$E$11 -> 0.25 | W20: 1 | X20: =MAX(0,Parametros!$E$12-Parametros!$E$18*W20) -> 0.2 | Y20: 5 | Z20: 2 | AA20: =IF(Y20>=Parametros!$E$22,Parametros!$E$24,0) -> 0 | AB20: =IF(Z20>=Parametros!$E$23,Parametros!$E$25,0) -> 0 | AC20: =AA20+AB20 -> 0 | AD20: 0 | AE20: SI | AF20: 0 | AG20: SI | AH20: 0 | AI20: SI | AJ20: 0 | AK20: SI | AL20: 0 | AM20: SI | AN20: =AD20*Parametros!$E$28+AF20*Parametros!$E$29+AH20*Parametros!$E$30+AJ20*Parametros!$E$31+AL20*Parametros!$E$32 -> 0 | AO20: =IF(OR(AND(AD20>0,AE20="NO"),AND(AF20>0,AG20="NO"),AND(AH20>0,AI20="NO"),AND(AJ20>0,AK20="NO"),AND(AL20>0,AM20="NO")),"SI","NO") -> NO | AP20: =G20+K20+N20+Q20+T20+V20+X20 -> 0.95 | AQ20: =MAX(0,MIN(1,MAX(0,AP20-IF(S20="NO",Parametros!$E$17,0))+AC20-AN20-IF(AO20="SI",Parametros!$E$33,0))) -> 0.95
AB21: 0
A23: NIVEL DE SEGURIDAD DE PLANTA (PROMEDIO DE AREAS) | AQ23: =AVERAGE(AQ6:AQ20) -> 0.93297436

Sheet Captura Febrero
A1: CAPTURA DE DATOS - FEBRERO | AS1: TABLERO NIVEL DE SEGURIDAD — FEBRERO 2026 | BB1: CULTURA — FEBRERO 2026
A2: Mes / Periodo: | B2: Febrero 2026 | F2: Instrucciones: | G2: Llenar SOLO las celdas en amarillo/azul. Las columnas de % y Nota se calculan automaticamente. Marcar 'NO' en las columnas de '¿Se realizo?' cuando una auto-evaluacion/cruzada no se hizo en su semana asignada. | AT2: CONTROLAR | AW2: CAPACITAR | AX2: CUIDAR | BB2: Tipo | BC2: Total mes
AS3: Área | AT3: Auto Evaluaciones (AE1+AE2+AE3) | AU3: Evaluación Cruzada | AV3: Inspección SSO | AW3: Capacita- ciones | AX3: Acciones Correctivas | AY3: Actos y Condiciones | AZ3: Accidenta- bilidad | BA3: Nivel de Seguridad | BB3: 🔶 Actos Inseguros | BC3: 63
D4: CAPACITACIONES (20%) | H4: AUTO EVALUACION 1 (8%) | L4: AUTO EVALUACION 2 (8%) | O4: AUTO EVALUACION 3 (8%) | R4: CRUZADA 4 (6%) | U4: INSPECCION SSO (25%) | W4: ACCIONES CORRECTIVAS/PREVENTIVAS (25%) | Y4: CULTURA (Bonificacion +8% max) | AD4: ACCIDENTABILIDAD (Penalizacion) | AP4: RESULTADO | AS4: ='Captura Febrero'!B6 -> Almacen de Repuestos | AT4: ='Captura Febrero'!K6+'Captura Febrero'!N6+'Captura Febrero'!Q6 -> 0.24 | AU4: ='Captura Febrero'!T6 -> 0.06 | AV4: ='Captura Febrero'!V6 -> 0.25 | AW4: ='Captura Febrero'!G6 -> 0.2 | AX4: ='Captura Febrero'!X6 -> 0.25 | AY4: ='Captura Febrero'!AC6 -> 0.04 | AZ4: =-'Captura Febrero'!AN6 -> 0 | BA4: ='Captura Febrero'!AQ6 -> 1 | BB4: 🔷 Condiciones Inseguras | BC4: 185
A5: No. | B5: Area | C5: Encargado | D5: % Quincena 1 (input) | E5: % Quincena 2 (input) | F5: Promedio (auto) | G5: Nota Categoria (auto) | H5: Correctas | I5: Total Preguntas | J5: ¿Se realizo? | K5: Nota Categoria (auto) | L5: % Cumplimiento (input) | M5: ¿Se realizo? | N5: Nota Categoria (auto) | O5: % Cumplimiento (input) | P5: ¿Se realizo? | Q5: Nota Categoria (auto) | R5: % Cumplimiento (input) | S5: ¿Se realizo? | T5: Nota Categoria (auto) | U5: % Resultado Checklist | V5: Nota Categoria (auto) | W5: No. Acciones Vencidas | X5: Nota Categoria (auto) | Y5: Actos Validados | Z5: Condiciones Validadas | AA5: Bono Actos (auto) | AB5: Bono Cond. (auto) | AC5: Bono Total (auto) | AD5: Incidentes (No.) | AE5: Incid. ¿Reportado? | AF5: FAI (No.) | AG5: FAI ¿Reportado? | AH5: MTI (No.) | AI5: MTI ¿Reportado? | AJ5: MDI (No.) | AK5: MDI ¿Reportado? | AL5: LTI (No.) | AM5: LTI ¿Reportado? | AN5: Penaliz. Total (auto) | AO5: ¿Sin reportar? (auto) | AP5: Subtotal (suma notas) | AQ5: Nivel de Seguridad Final (auto) | AS5: ='Captura Febrero'!B7 -> Alrededores | AT5: ='Captura Febrero'!K7+'Captura Febrero'!N7+'Captura Febrero'!Q7 -> 0.24 | AU5: ='Captura Febrero'!T7 -> 0.06 | AV5: ='Captura Febrero'!V7 -> 0.25 | AW5: ='Captura Febrero'!G7 -> 0.19 | AX5: ='Captura Febrero'!X7 -> 0.25 | AY5: ='Captura Febrero'!AC7 -> 0.04 | AZ5: =-'Captura Febrero'!AN7 -> 0 | BA5: ='Captura Febrero'!AQ7 -> 1 | BB5: ↑ Ingresa el total del mes en celdas amarillas
A6: 1 | B6: Almacen de Repuestos | C6: =VLOOKUP(B6,Parametros!$I$6:$J$20,2,FALSE()) -> Fredy Fuentes | D6: 1 | E6: 1 | F6: =AVERAGE(D6,E6) -> 1 | G6: =F6*Parametros!$E$6 -> 0.2 | H6: 10 | I6: 10 | J6: SI | K6: =IF(J6="NO",0,IFERROR(H6/I6,0)*Parametros!$E$7) -> 0.08 | L6: 1 | M6: SI | N6: =IF(M6="NO",0,L6*Parametros!$E$8) -> 0.08 | O6: 1 | P6: SI | Q6: =IF(P6="NO",0,O6*Parametros!$E$9) -> 0.08 | R6: 1 | S6: SI | T6: =IF(S6="NO",0,R6*Parametros!$E$10) -> 0.06 | U6: 1 | V6: =U6*Parametros!$E$11 -> 0.25 | W6: 0 | X6: =MAX(0,Parametros!$E$12-Parametros!$E$18*W6) -> 0.25 | Y6: 11 | Z6: 2 | AA6: =IF(Y6>=Parametros!$E$22,Parametros!$E$24,0) -> 0.04 | AB6: =IF(Z6>=Parametros!$E$23,Parametros!$E$25,0) -> 0 | AC6: =AA6+AB6 -> 0.04 | AD6: 0 | AE6: SI | AF6: 0 | AG6: SI | AH6: 0 | AI6: SI | AJ6: 0 | AK6: SI | AL6: 0 | AM6: SI | AN6: =AD6*Parametros!$E$28+AF6*Parametros!$E$29+AH6*Parametros!$E$30+AJ6*Parametros!$E$31+AL6*Parametros!$E$32 -> 0 | AO6: =IF(OR(AND(AD6>0,AE6="NO"),AND(AF6>0,AG6="NO"),AND(AH6>0,AI6="NO"),AND(AJ6>0,AK6="NO"),AND(AL6>0,AM6="NO")),"SI","NO") -> NO | AP6: =G6+K6+N6+Q6+T6+V6+X6 -> 1 | AQ6: =MAX(0,MIN(1,MAX(0,AP6-IF(S6="NO",Parametros!$E$17,0))+AC6-AN6-IF(AO6="SI",Parametros!$E$33,0))) -> 1 | AS6: ='Captura Febrero'!B8 -> Calidad | AT6: ='Captura Febrero'!K8+'Captura Febrero'!N8+'Captura Febrero'!Q8 -> 0.24 | AU6: ='Captura Febrero'!T8 -> 0.06 | AV6: ='Captura Febrero'!V8 -> 0.25 | AW6: ='Captura Febrero'!G8 -> 0.2 | AX6: ='Captura Febrero'!X8 -> 0.25 | AY6: ='Captura Febrero'!AC8 -> 0.08 | AZ6: =-'Captura Febrero'!AN8 -> 0 | BA6: ='Captura Febrero'!AQ8 -> 1
A7: 2 | B7: Alrededores | C7: =VLOOKUP(B7,Parametros!$I$6:$J$20,2,FALSE()) -> Carlos Chavez | D7: 0.9 | E7: 1 | F7: =AVERAGE(D7,E7) -> 0.95 | G7: =F7*Parametros!$E$6 -> 0.19 | H7: 10 | I7: 10 | J7: SI | K7: =IF(J7="NO",0,IFERROR(H7/I7,0)*Parametros!$E$7) -> 0.08 | L7: 1 | M7: SI | N7: =IF(M7="NO",0,L7*Parametros!$E$8) -> 0.08 | O7: 1 | P7: SI | Q7: =IF(P7="NO",0,O7*Parametros!$E$9) -> 0.08 | R7: 1 | S7: SI | T7: =IF(S7="NO",0,R7*Parametros!$E$10) -> 0.06 | U7: 1 | V7: =U7*Parametros!$E$11 -> 0.25 | W7: 0 | X7: =MAX(0,Parametros!$E$12-Parametros!$E$18*W7) -> 0.25 | Y7: 0 | Z7: 13 | AA7: =IF(Y7>=Parametros!$E$22,Parametros!$E$24,0) -> 0 | AB7: =IF(Z7>=Parametros!$E$23,Parametros!$E$25,0) -> 0.04 | AC7: =AA7+AB7 -> 0.04 | AD7: 0 | AE7: SI | AF7: 0 | AG7: SI | AH7: 0 | AI7: SI | AJ7: 0 | AK7: SI | AL7: 0 | AM7: SI | AN7: =AD7*Parametros!$E$28+AF7*Parametros!$E$29+AH7*Parametros!$E$30+AJ7*Parametros!$E$31+AL7*Parametros!$E$32 -> 0 | AO7: =IF(OR(AND(AD7>0,AE7="NO"),AND(AF7>0,AG7="NO"),AND(AH7>0,AI7="NO"),AND(AJ7>0,AK7="NO"),AND(AL7>0,AM7="NO")),"SI","NO") -> NO | AP7: =G7+K7+N7+Q7+T7+V7+X7 -> 0.99 | AQ7: =MAX(0,MIN(1,MAX(0,AP7-IF(S7="NO",Parametros!$E$17,0))+AC7-AN7-IF(AO7="SI",Parametros!$E$33,0))) -> 1 | AS7: ='Captura Febrero'!B9 -> Centro de Distribucion | AT7: ='Captura Febrero'!K9+'Captura Febrero'!N9+'Captura Febrero'!Q9 -> 0.24 | AU7: ='Captura Febrero'!T9 -> 0.06 | AV7: ='Captura Febrero'!V9 -> 0.25 | AW7: ='Captura Febrero'!G9 -> 0.1975 | AX7: ='Captura Febrero'!X9 -> 0.25 | AY7: ='Captura Febrero'!AC9 -> 0.04 | AZ7: =-'Captura Febrero'!AN9 -> 0 | BA7: ='Captura Febrero'!AQ9 -> 1
A8: 3 | B8: Calidad | C8: =VLOOKUP(B8,Parametros!$I$6:$J$20,2,FALSE()) -> Alejandro Martinez | D8: 1 | E8: 1 | F8: =AVERAGE(D8,E8) -> 1 | G8: =F8*Parametros!$E$6 -> 0.2 | H8: 10 | I8: 10 | J8: SI | K8: =IF(J8="NO",0,IFERROR(H8/I8,0)*Parametros!$E$7) -> 0.08 | L8: 1 | M8: SI | N8: =IF(M8="NO",0,L8*Parametros!$E$8) -> 0.08 | O8: 1 | P8: SI | Q8: =IF(P8="NO",0,O8*Parametros!$E$9) -> 0.08 | R8: 1 | S8: SI | T8: =IF(S8="NO",0,R8*Parametros!$E$10) -> 0.06 | U8: 1 | V8: =U8*Parametros!$E$11 -> 0.25 | W8: 0 | X8: =MAX(0,Parametros!$E$12-Parametros!$E$18*W8) -> 0.25 | Y8: 14 | Z8: 27 | AA8: =IF(Y8>=Parametros!$E$22,Parametros!$E$24,0) -> 0.04 | AB8: =IF(Z8>=Parametros!$E$23,Parametros!$E$25,0) -> 0.04 | AC8: =AA8+AB8 -> 0.08 | AD8: 0 | AE8: SI | AF8: 0 | AG8: SI | AH8: 0 | AI8: SI | AJ8: 0 | AK8: SI | AL8: 0 | AM8: SI | AN8: =AD8*Parametros!$E$28+AF8*Parametros!$E$29+AH8*Parametros!$E$30+AJ8*Parametros!$E$31+AL8*Parametros!$E$32 -> 0 | AO8: =IF(OR(AND(AD8>0,AE8="NO"),AND(AF8>0,AG8="NO"),AND(AH8>0,AI8="NO"),AND(AJ8>0,AK8="NO"),AND(AL8>0,AM8="NO")),"SI","NO") -> NO | AP8: =G8+K8+N8+Q8+T8+V8+X8 -> 1 | AQ8: =MAX(0,MIN(1,MAX(0,AP8-IF(S8="NO",Parametros!$E$17,0))+AC8-AN8-IF(AO8="SI",Parametros!$E$33,0))) -> 1 | AS8: ='Captura Febrero'!B10 -> ETEI | AT8: ='Captura Febrero'!K10+'Captura Febrero'!N10+'Captura Febrero'!Q10 -> 0.16 | AU8: ='Captura Febrero'!T10 -> 0.06 | AV8: ='Captura Febrero'!V10 -> 0.25 | AW8: ='Captura Febrero'!G10 -> 0.125 | AX8: ='Captura Febrero'!X10 -> 0.25 | AY8: ='Captura Febrero'!AC10 -> 0 | AZ8: =-'Captura Febrero'!AN10 -> 0 | BA8: ='Captura Febrero'!AQ10 -> 0.845
